<?xml version='1.0'?>

<robot name="udacity_bot" xmlns:xacro="http://www.ros.org/wiki/xacro">
<xacro:include filename="$(find udacity_bot)/urdf/udacity_bot.gazebo" />

  <link name="robot_footprint"></link>

  <joint name="robot_footprint_joint" type="fixed">
    <origin xyz="0 0 0" rpy="0 0 0" />
    <parent link="robot_footprint"/>
    <child link="chassis" />
  </joint>

  <link name='chassis'>
	<pose>0 0 0.1 0 0 0</pose>
	<inertial>
		<mass value="0.5"/>
		<origin xyz="0.0 0 0" rpy=" 0 0 0"/>
		<inertia
			  ixx="0.1" ixy="0" ixz="0"
			  iyy="0.1" iyz="0"
			  izz="0.1"
		/>
	</inertial>

	<collision name='chassis_collision'>
		<origin xyz="0 0 0" rpy=" 0 0 0"/> 
     		<geometry>
     			<box size=".24 .1 .02"/>
    		</geometry>
	</collision>

	<visual name='chassis_visual'>
		  <origin xyz="0 0 0" rpy=" 0 0 0"/>
		  <geometry>
			<box size=".24 .1 .02"/>
		  </geometry>
	</visual>


		<visual name="rightb_wheel_visual" >
		<origin xyz="-0.06 0.07 0" rpy="1.570796 0 0"/>
			  <geometry>
				<cylinder length="0.025" radius="0.0335"/>
			  </geometry>
		</visual>
		
		<inertial>
			  <mass value="0.033"/>
			  <origin xyz="0.0 0 0" rpy=" 0 0 0"/>
			  <inertia
				  ixx="0.1" ixy="0" ixz="0"
				  iyy="0.1" iyz="0"
				  izz="0.1"
			  />
    	  	</inertial>
    
		<collision name="rightb_wheel_collision">
			<origin xyz="-0.06 0.07 0" rpy="1.570796 0 0"/>
			  <geometry>
				<cylinder length="0.025" radius="0.0335"/>
			  </geometry>
		 <surface>
        		<friction>
         		 <ode>
         		   <mu>0</mu>
          		  <mu2>0</mu2>
           		 <slip1>1.0</slip1>
          		  <slip2>1.0</slip2>
         			 </ode>
       			 </friction>
      </surface>

		</collision>



		<visual name="leftb_wheel_visual">
		<origin xyz="-0.06 -0.07 0" rpy="1.570796 0 0"/>
			  <geometry>
				<cylinder length="0.025" radius="0.0335"/>
			  </geometry>
		</visual>
		<inertial>
			  <mass value="0.033"/>
			  <origin xyz="0.0 0 0" rpy=" 0 0 0"/>
			  <inertia
				  ixx="0.1" ixy="0" ixz="0"
				  iyy="0.1" iyz="0"
				  izz="0.1"
			  />
    		</inertial>
		<collision name="leftb_wheel_collision">
		<origin xyz="-0.06 -0.07 0" rpy="1.570796 0 0"/>
			  <geometry>
				<cylinder length="0.025" radius="0.0335"/>
			  </geometry>
 			<surface>
        		 <friction>
         		 	<ode>
         		 	  <mu>0</mu>
          		 	 <mu2>0</mu2>
           			 <slip1>1.0</slip1>
          			  <slip2>1.0</slip2>
         			 </ode>
       			 </friction>
      			</surface>
		</collision>
  </link>

	<link name='rightf_wheel'>
		<visual>
		 <origin xyz="0.0 0 0" rpy=" 0 0 0"/>
			  <geometry>
				<cylinder length="0.025" radius="0.0335"/>
			  </geometry>
		</visual>
		
		<inertial>
			  <mass value="0.033"/>
			  <origin xyz="0.0 0 0" rpy=" 0 0 0"/>
			  <inertia
				  ixx="0.1" ixy="0" ixz="0"
				  iyy="0.1" iyz="0"
				  izz="0.1"
			  />
    		</inertial>
    
		<collision>
		<origin xyz="0.0 0 0" rpy=" 0 0 0"/>
			  <geometry>
				<cylinder length="0.025" radius="0.0335"/>
			  </geometry>
			</collision>
	</link>
	<link name='leftf_wheel'>
		<visual>
			  <geometry>
				<cylinder length="0.025" radius="0.0335"/>
			  </geometry>
		</visual>
		<inertial>
			  <mass value="0.033"/>
			  <origin xyz="0.0 0 0" rpy=" 0 0 0"/>
			  <inertia
				  ixx="0.1" ixy="0" ixz="0"
				  iyy="0.1" iyz="0"
				  izz="0.1"
			  />
    		</inertial>
		<collision>
			  <origin xyz="0 0 0" rpy=" 0 0 0"/> 
			  <geometry>
				<cylinder length="0.025" radius="0.03"/>
			  </geometry>
		</collision>
	</link>

	<link name="camera">
     <visual>
     	<origin xyz="0 0 0" rpy="0 0 0"/>
       <geometry>
        <box size=".05 .05 .05"/>
      </geometry>
    </visual>

    <inertial>
      <mass value="0.01"/>
      <origin xyz="0 0 0" rpy=" 0 0 0"/>
      <inertia
          ixx="0.000001" ixy="0" ixz="0"
          iyy="0.000001" iyz="0"
          izz="0.000001"
      />
    </inertial>

    <collision>
      <origin xyz="0 0 0" rpy="0 0 0"/>
       <geometry>
        <box size=".05 .05 .05"/>
      </geometry>
    </collision>

</link>


<link name="hokuyo">
     <visual>
      <origin xyz="0 0 0" rpy="0 0 0"/>
       <geometry>
	<mesh filename="package://udacity_bot/meshes/hokuyo.dae"/>
      </geometry>
    </visual>

    <inertial>
      <mass value="0.1"/>
      <origin xyz="0 0 0" rpy=" 0 0 0"/>
      <inertia
          ixx="0.000001" ixy="0" ixz="0"
          iyy="0.000001" iyz="0"
          izz="0.000001"
      />
    </inertial>

	    <collision>
	      <origin xyz="0 0 0" rpy="0 0 0"/>
	       <geometry>
	        <box size=".05 .05 .05"/>
	      </geometry>
	    </collision>
	</link>

	  <joint name="hokuyo_joint" type="fixed">
	    <origin xyz="0.13 0 0.127" rpy="0 0 0"/>
	    <parent link="chassis"/>
	    <child link="hokuyo"/>
	  </joint>


	<joint type="fixed" name="camera_joint">
		<origin xyz="0.13 0.05 0.07" rpy="0 0 0"/>
		<child link="camera"/>
		<parent link="chassis"/>
		<axis xyz="0 0 0" rpy="0 0 0"/>
  	</joint>



	<joint type="continuous" name="left__front_wheel_hinge">
		<origin xyz="0.06 0.07 0" rpy="1.570796 0 0"/>
		<child link="leftf_wheel"/>
		<parent link="chassis"/>
		<axis xyz="0 0 1" rpy="0 0 0"/>
		<limit effort="10000" velocity="1000"/>
		<joint_properties damping="1.0" friction="0.0"/>
  	</joint>
  	
  	<joint type="continuous" name="right_front_wheel_hinge">
		<origin xyz="0.06 -0.07 0" rpy="1.570796 0 0"/>
		<child link="rightf_wheel"/>
		<parent link="chassis"/>
		<axis xyz="0 0 1" rpy="0 0 0"/>
		<limit effort="10000" velocity="1000"/>
		<joint_properties damping="1.0" friction="0.0"/>
  	</joint>
</robot>
